Workbook
Name Slicer_Business_Unit: #N/A
Name Slicer_Country: #N/A
Name Slicer_Department: #N/A
Name Slicer_Department1: #N/A
Name Slicer_Gender: #N/A
Name Slicer_Item: #N/A
Name Slicer_Sales_Rep: #N/A
Name Slicer_State: #N/A

Sheet EMp Steps
B2: 1 - Extracted Data From Excel Workbook ( Raw Data )
B3: 2 - Transformation -
C4: a - Remove Errors
C5: b - Remove Blank Records
C6: c - Remove Duplicated Records
C7: d - Remove Blank/Null Values
C8: e - Identify PK if Not Add PK | F8: EmployeeID | G8: EMP-1
B9: 3 - Ask Questions Add Columns if Nec
C10: 1 - While adding a new Always Check Its Data type
C11: 2 - Added Age Group
C12: 3 - Total Salary
C13: 4 - Left Status

Sheet Sales Raw Data
A1: Date | B1: Item | C1: Sales Rep | D1: Quantity | E1: Price | F1: Commission | G1: State
A2: 43282 | B2: Printer | C2: John | D2: 6 | E2: 80 | F2: 0.01 | G2: Meghalaya
A3: 43282 | B3: White Board | C3: Mark | D3: 14 | E3: 40 | F3: 0.06 | G3: Uttar Pradesh
A4: 43282 | B4: Office Chair | C4: Mark | D4: 22 | E4: 230 | F4: 0.11 | G4: Maharashtra
A5: 43282 | B5: Office Chair | C5: John | D5: 8 | E5: 230 | F5: 0.03 | G5: Delhi
A6: 43282 | B6: Office Chair | C6: Laura | D6: 12 | E6: 230 | F6: 0.03 | G6: West Bengal
A7: 43282 | B7: Printer | C7: Stacey | D7: 19 | E7: 80 | F7: 0.02 | G7: Bihar
A8: 43282 | B8: Diary | C8: Bob | D8: 17 | E8: 16 | F8: 0.08 | G8: Goa
A9: 43282 | B9: Projector | C9: Stacey | D9: 7 | E9: 150 | F9: 0.05 | G9: Karnataka
A10: 43282 | B10: Projector | C10: Stacey | D10: 20 | E10: 150 | F10: 0.1 | G10: Gujarat
A11: 43282 | B11: Diary | C11: John | D11: 21 | E11: 16 | F11: 0.09 | G11: Jharkhand
A12: 43282 | B12: Office Chair | C12: Mark | D12: 7 | E12: 230 | F12: 0.01 | G12: Haryana
A13: 43283 | B13: Printer | C13: Stacey | D13: 7 | E13: 80 | F13: 0.07 | G13: Kerala
... A1304: 43312 | B1304: White Board | C1304: Laura | D1304: 13 | E1304: 40 | F1304: 0.02 | G1304: Delhi

Sheet sales main data
A1: Order ID | B1: Date | C1: Item | D1: Sales Rep | E1: Quantity | F1: Price | G1: Total sales | H1: Commission | I1: Total commisstion | J1: State
A2: Ord-1 | B2: 43282 | C2: Printer | D2: John | E2: 6 | F2: 80 | G2: 480 | H2: 0.01 | I2: 4.8 | J2: Meghalaya
A3: Ord-2 | B3: 43282 | C3: White Board | D3: Mark | E3: 14 | F3: 40 | G3: 560 | H3: 0.06 | I3: 33.6 | J3: Uttar Pradesh
A4: Ord-3 | B4: 43282 | C4: Office Chair | D4: Mark | E4: 22 | F4: 230 | G4: 5060 | H4: 0.11 | I4: 556.6 | J4: Maharashtra
A5: Ord-4 | B5: 43282 | C5: Office Chair | D5: John | E5: 8 | F5: 230 | G5: 1840 | H5: 0.03 | I5: 55.2 | J5: Delhi
A6: Ord-5 | B6: 43282 | C6: Office Chair | D6: Laura | E6: 12 | F6: 230 | G6: 2760 | H6: 0.03 | I6: 82.8 | J6: West Bengal
A7: Ord-6 | B7: 43282 | C7: Printer | D7: Stacey | E7: 19 | F7: 80 | G7: 1520 | H7: 0.02 | I7: 30.4 | J7: Bihar
A8: Ord-7 | B8: 43282 | C8: Diary | D8: Bob | E8: 17 | F8: 16 | G8: 272 | H8: 0.08 | I8: 21.76 | J8: Goa
A9: Ord-8 | B9: 43282 | C9: Projector | D9: Stacey | E9: 7 | F9: 150 | G9: 1050 | H9: 0.05 | I9: 52.5 | J9: Karnataka
A10: Ord-9 | B10: 43282 | C10: Projector | D10: Stacey | E10: 20 | F10: 150 | G10: 3000 | H10: 0.1 | I10: 300 | J10: Gujarat
A11: Ord-10 | B11: 43282 | C11: Diary | D11: John | E11: 21 | F11: 16 | G11: 336 | H11: 0.09 | I11: 30.24 | J11: Jharkhand
A12: Ord-11 | B12: 43282 | C12: Office Chair | D12: Mark | E12: 7 | F12: 230 | G12: 1610 | H12: 0.01 | I12: 16.1 | J12: Haryana
A13: Ord-12 | B13: 43283 | C13: Printer | D13: Stacey | E13: 7 | F13: 80 | G13: 560 | H13: 0.07 | I13: 39.2 | J13: Kerala
... A1301: Ord-1300 | B1301: 43312 | C1301: White Board | D1301: Laura | E1301: 13 | F1301: 40 | G1301: 520 | H1301: 0.02 | I1301: 10.4 | J1301: Delhi

Sheet Sheet1
F1: One Month Sales Report
B2: Count of Order ID | C2: Sum of Quantity | D2: Sum of Total sales | H2: Sum of Total commisstion | J2: Net sales | L2: Sum of State
B3: 1300 | C3: 16632 | D3: 1584826 | H3: 100157.04 | J3: =GETPIVOTDATA("Total sales ",$D$2)-GETPIVOTDATA("Total commisstion",$H$2) -> 1484669 | L3: =COUNTA(G47:G58) -> 12
H45: Row Labels | I45: Count of Order ID
B46: Row Labels | C46: Count of Order ID | G46: Row Labels | H46: Bihar | I46: 104 | M46: =H46 -> Bihar | N46: =I46 -> 104
B47: 43282 | C47: 39 | G47: Bihar | H47: Delhi | I47: 105 | M47: =H47 -> Delhi | N47: =I47 -> 105
B48: 43283 | C48: 33 | E48: Row Labels | F48: Sum of Quantity | G48: Delhi | H48: Goa | I48: 120 | M48: =H48 -> Goa | N48: =I48 -> 120
B49: 43284 | C49: 36 | E49: Diary | F49: 3071 | G49: Goa | H49: Gujarat | I49: 163 | M49: =H49 -> Gujarat | N49: =I49 -> 163
B50: 43285 | C50: 35 | E50: Office Chair | F50: 2648 | G50: Gujarat | H50: Haryana | I50: 68 | M50: =H50 -> Haryana | N50: =I50 -> 68
B51: 43286 | C51: 42 | E51: Printer | F51: 3819 | G51: Haryana | H51: Jharkhand | I51: 119 | J51: Row Labels | K51: Sum of Total sales | M51: =H51 -> Jharkhand | N51: =I51 -> 119
B52: 43287 | C52: 47 | E52: Projector | F52: 3067 | G52: Jharkhand | H52: Karnataka | I52: 119 | J52: Bob | K52: 306530 | M52: =H52 -> Karnataka | N52: =I52 -> 119
B53: 43288 | C53: 53 | E53: White Board | F53: 4027 | G53: Karnataka | H53: Kerala | I53: 68 | J53: John | K53: 319900 | M53: =H53 -> Kerala | N53: =I53 -> 68
B54: 43289 | C54: 50 | E54: Grand Total | F54: 16632 | G54: Kerala | H54: Maharashtra | I54: 150 | J54: Laura | K54: 307656 | M54: =H54 -> Maharashtra | N54: =I54 -> 150
B55: 43290 | C55: 38 | G55: Maharashtra | H55: Meghalaya | I55: 76 | J55: Mark | K55: 321258 | M55: =H55 -> Meghalaya | N55: =I55 -> 76
B56: 43291 | C56: 50 | E56: Row Labels | F56: Sum of Commission | G56: Meghalaya | H56: Uttar Pradesh | I56: 105 | J56: Stacey | K56: 329482 | M56: =H56 -> Uttar Pradesh | N56: =I56 -> 105
B57: 43292 | C57: 43 | E57: Bob | F57: 17.43 | G57: Uttar Pradesh | H57: West Bengal | I57: 103 | J57: Grand Total | K57: 1584826 | M57: =H57 -> West Bengal | N57: =I57 -> 103
B58: 43293 | C58: 30 | E58: John | F58: 17.18 | G58: West Bengal | H58: Grand Total | I58: 1300
B59: 43294 | C59: 48 | E59: Laura | F59: 14.38 | G59: Grand Total
B60: 43295 | C60: 46 | E60: Mark | F60: 14.87
B61: 43296 | C61: 45 | E61: Stacey | F61: 15.98
B62: 43297 | C62: 48 | E62: Grand Total | F62: 79.84
B63: 43298 | C63: 48
B64: 43299 | C64: 41
B65: 43300 | C65: 44
B66: 43301 | C66: 34
B67: 43302 | C67: 47
B68: 43303 | C68: 38
B69: 43304 | C69: 39
B70: 43305 | C70: 46
B71: 43306 | C71: 49
B72: 43307 | C72: 47
B73: 43308 | C73: 52
B74: 43309 | C74: 37
... B77: 43312 | C77: 25
B78: Grand Total | C78: 1300

Sheet Dashboard one month sales
B3: Total Order | E3: Total Commisstion | H3: One Month Sales report | P3: Net sales | S3: Total sales
B4: =Sheet1!$B$3 -> 1300 | E4: =Sheet1!$H$3 -> 100157.04 | P4: =Sheet1!$J$3 -> 1484669 | S4: =Sheet1!$D$3 -> 1584826

Sheet EMP RAW Data
A1: Job Title | B1: Department | C1: Business Unit | D1: Gender | E1: Age | F1: Hire Date | G1: Annual Salary | H1: Bonus % | I1: Country | J1: City | K1: Exit Date
A2: Sr. Manger | B2: IT | C2: Research & Development | D2: Female | E2: 55 | F2: 42468 | G2: 141604 | H2: 0.15 | I2: United States | J2: Seattle | K2: 44485
A3: Technical Architect | B3: IT | C3: Manufacturing | D3: Male | E3: 59 | F3: 35763 | G3: 99975 | H3: 0 | I3: China | J3: Chongqing
A4: Director | B4: Finance | C4: Speciality Products | D4: Female | E4: 50 | F4: 39016 | G4: 163099 | H4: 0.2 | I4: United States | J4: Chicago
A5: Computer Systems Manager | B5: IT | C5: Manufacturing | D5: Female | E5: 26 | F5: 43735 | G5: 84913 | H5: 0.07 | I5: United States | J5: Chicago
A6: Sr. Analyst | B6: Finance | C6: Manufacturing | D6: Male | E6: 55 | F6: 35023 | G6: 95409 | H6: 0 | I6: United States | J6: Phoenix
A7: Account Representative | B7: Sales | C7: Corporate | D7: Male | E7: 57 | F7: 42759 | G7: 50994 | H7: 0 | I7: China | J7: Chongqing
A8: Manager | B8: IT | C8: Corporate | D8: Female | E8: 27 | F8: 44013 | G8: 119746 | H8: 0.1 | I8: United States | J8: Phoenix
A9: Analyst | B9: Finance | C9: Manufacturing | D9: Male | E9: 25 | F9: 43967 | G9: 41336 | H9: 0 | I9: United States | J9: Miami | K9: 44336
A10: Manager | B10: Accounting | C10: Manufacturing | D10: Male | E10: 29 | F10: 43490 | G10: 113527 | H10: 0.06 | I10: United States | J10: Austin
A11: Sr. Analyst | B11: Finance | C11: Speciality Products | D11: Female | E11: 34 | F11: 43264 | G11: 77203 | H11: 0 | I11: United States | J11: Chicago
A12: Sr. Manger | B12: Human Resources | C12: Manufacturing | D12: Female | E12: 36 | F12: 39855 | G12: 157333 | H12: 0.15 | I12: United States | J12: Miami
A13: Controls Engineer | B13: Engineering | C13: Speciality Products | D13: Female | E13: 27 | F13: 44490 | G13: 109851 | H13: 0 | I13: United States | J13: Seattle
A14: Manager | B14: Human Resources | C14: Manufacturing | D14: Male | E14: 59 | F14: 36233 | G14: 105086 | H14: 0.09 | I14: United States | J14: Austin
A15: Sr. Manger | B15: Finance | C15: Research & Development | D15: Female | E15: 51 | F15: 44357 | G15: 146742 | H15: 0.1 | I15: China | J15: Shanghai
A16: Sr. Analyst | B16: Accounting | C16: Speciality Products | D16: Male | E16: 31 | F16: 43043 | G16: 97078 | H16: 0 | I16: United States | J16: Austin | K16: 43899
A17: Vice President | B17: Marketing | C17: Research & Development | D17: Female | E17: 41 | F17: 41346 | G17: 249270 | H17: 0.3 | I17: United States | J17: Seattle
A18: Director | B18: Finance | C18: Research & Development | D18: Female | E18: 65 | F18: 37319 | G18: 175837 | H18: 0.2 | I18: United States | J18: Phoenix
A19: Sr. Manger | B19: Marketing | C19: Speciality Products | D19: Female | E19: 64 | F19: 37956 | G19: 154828 | H19: 0.13 | I19: United States | J19: Seattle
A20: Director | B20: IT | C20: Corporate | D20: Male | E20: 64 | F20: 41581 | G20: 186503 | H20: 0.24 | I20: United States | J20: Columbus
A21: Director | B21: Sales | C21: Research & Development | D21: Male | E21: 45 | F21: 37446 | G21: 166331 | H21: 0.18 | I21: China | J21: Chongqing
A22: Sr. Manger | B22: IT | C22: Manufacturing | D22: Male | E22: 56 | F22: 40917 | G22: 146140 | H22: 0.1 | I22: Brazil | J22: Manaus
A23: Director | B23: Sales | C23: Manufacturing | D23: Female | E23: 36 | F23: 44288 | G23: 151703 | H23: 0.21 | I23: United States | J23: Miami
A24: Director | B24: IT | C24: Research & Development | D24: Male | E24: 59 | F24: 37400 | G24: 172787 | H24: 0.28 | I24: Brazil | J24: Rio de Janerio
A25: Analyst | B25: Sales | C25: Speciality Products | D25: Male | E25: 37 | F25: 43713 | G25: 49998 | H25: 0 | I25: United States | J25: Seattle
A26: Vice President | B26: Sales | C26: Speciality Products | D26: Male | E26: 44 | F26: 41700 | G26: 207172 | H26: 0.31 | I26: China | J26: Chongqing
A27: Director | B27: Human Resources | C27: Speciality Products | D27: Male | E27: 41 | F27: 42111 | G27: 152239 | H27: 0.23 | I27: United States | J27: Columbus
A28: Quality Engineer | B28: Engineering | C28: Corporate | D28: Female | E28: 56 | F28: 38388 | G28: 98581 | H28: 0 | I28: Brazil | J28: Rio de Janerio
... A41: Enterprise Architect | B41: IT | C41: Corporate | D41: Female | E41: 57 | F41: 34337 | G41: 82872 | H41: 0 | I41: Brazil | J41: Manaus
A42: Sr. Business Partner | B42: Human Resources | C42: Speciality Products | D42: Male | E42: 30 | F42: 42884 | G42: 86317 | H42: 0 | I42: China | J42: Chengdu | K42: 42932
A43: Manager | B43: Marketing | C43: Speciality Products | D43: Female | E43: 53 | F43: 41601 | G43: 113135 | H43: 0.05 | I43: United States | J43: Austin
A44: Vice President | B44: IT | C44: Speciality Products | D44: Male | E44: 52 | F44: 38664 | G44: 199808 | H44: 0.32 | I44: United States | J44: Seattle
A45: Account Representative | B45: Sales | C45: Speciality Products | D45: Male | E45: 37 | F45: 41592 | G45: 56037 | H45: 0 | I45: China | J45: Shanghai
A46: Sr. Manger | B46: Marketing | C46: Research & Development | D46: Female | E46: 29 | F46: 43609 | G46: 122350 | H46: 0.12 | I46: United States | J46: Phoenix
A47: Enterprise Architect | B47: IT | C47: Research & Development | D47: Male | E47: 40 | F47: 40486 | G47: 92952 | H47: 0 | I47: United States | J47: Seattle
A48: Computer Systems Manager | B48: IT | C48: Corporate | D48: Male | E48: 32 | F48: 41353 | G48: 79921 | H48: 0.05 | I48: United States | J48: Austin
A49: Director | B49: IT | C49: Research & Development | D49: Female | E49: 37 | F49: 40076 | G49: 167199 | H49: 0.2 | I49: United States | J49: Seattle
A50: Quality Engineer | B50: Engineering | C50: Research & Development | D50: Male | E50: 52 | F50: 41199 | G50: 71476 | H50: 0 | I50: United States | J50: Phoenix
A51: Director | B51: Engineering | C51: Manufacturing | D51: Female | E51: 45 | F51: 41941 | G51: 189420 | H51: 0.2 | I51: United States | J51: Seattle
A52: HRIS Analyst | B52: Human Resources | C52: Research & Development | D52: Female | E52: 64 | F52: 37184 | G52: 64057 | H52: 0 | I52: United States | J52: Phoenix
...

Sheet EMP Table1
A1: EMP ID | B1: Job Title | C1: Department | D1: Business Unit | E1: Gender | F1: Age | G1: Age under | H1: Hire Date | I1: Annual Salary | J1: Bonus % | K1: Total salary | L1: Country | M1: City | N1: Exit Date
A2: Emp-1 | B2: Sr. Manger | C2: IT | D2: Research & Development | E2: Female | F2: 55 | G2: 55-65 | H2: 42468 | I2: 141604 | J2: 0.15 | K2: 21240.6 | L2: United States | M2: Seattle | N2: 44485
A3: Emp-2 | B3: Technical Architect | C3: IT | D3: Manufacturing | E3: Male | F3: 59 | G3: 55-65 | H3: 35763 | I3: 99975 | J3: 0 | K3: 0 | L3: China | M3: Chongqing
A4: Emp-3 | B4: Director | C4: Finance | D4: Speciality Products | E4: Female | F4: 50 | G4: 45-55 | H4: 39016 | I4: 163099 | J4: 0.2 | K4: 32619.8 | L4: United States | M4: Chicago
A5: Emp-4 | B5: Computer Systems Manager | C5: IT | D5: Manufacturing | E5: Female | F5: 26 | G5: 25-35 | H5: 43735 | I5: 84913 | J5: 0.07 | K5: 5943.91 | L5: United States | M5: Chicago
A6: Emp-5 | B6: Sr. Analyst | C6: Finance | D6: Manufacturing | E6: Male | F6: 55 | G6: 55-65 | H6: 35023 | I6: 95409 | J6: 0 | K6: 0 | L6: United States | M6: Phoenix
A7: Emp-6 | B7: Account Representative | C7: Sales | D7: Corporate | E7: Male | F7: 57 | G7: 55-65 | H7: 42759 | I7: 50994 | J7: 0 | K7: 0 | L7: China | M7: Chongqing
A8: Emp-7 | B8: Manager | C8: IT | D8: Corporate | E8: Female | F8: 27 | G8: 25-35 | H8: 44013 | I8: 119746 | J8: 0.1 | K8: 11974.6 | L8: United States | M8: Phoenix
A9: Emp-8 | B9: Analyst | C9: Finance | D9: Manufacturing | E9: Male | F9: 25 | G9: 25-35 | H9: 43967 | I9: 41336 | J9: 0 | K9: 0 | L9: United States | M9: Miami | N9: 44336
A10: Emp-9 | B10: Manager | C10: Accounting | D10: Manufacturing | E10: Male | F10: 29 | G10: 25-35 | H10: 43490 | I10: 113527 | J10: 0.06 | K10: 6811.62 | L10: United States | M10: Austin
A11: Emp-10 | B11: Sr. Analyst | C11: Finance | D11: Speciality Products | E11: Female | F11: 34 | G11: 25-35 | H11: 43264 | I11: 77203 | J11: 0 | K11: 0 | L11: United States | M11: Chicago
A12: Emp-11 | B12: Sr. Manger | C12: Human Resources | D12: Manufacturing | E12: Female | F12: 36 | G12: 35-45 | H12: 39855 | I12: 157333 | J12: 0.15 | K12: 23599.95 | L12: United States | M12: Miami
A13: Emp-12 | B13: Controls Engineer | C13: Engineering | D13: Speciality Products | E13: Female | F13: 27 | G13: 25-35 | H13: 44490 | I13: 109851 | J13: 0 | K13: 0 | L13: United States | M13: Seattle
A14: Emp-13 | B14: Manager | C14: Human Resources | D14: Manufacturing | E14: Male | F14: 59 | G14: 55-65 | H14: 36233 | I14: 105086 | J14: 0.09 | K14: 9457.74 | L14: United States | M14: Austin
A15: Emp-14 | B15: Sr. Manger | C15: Finance | D15: Research & Development | E15: Female | F15: 51 | G15: 45-55 | H15: 44357 | I15: 146742 | J15: 0.1 | K15: 14674.2 | L15: China | M15: Shanghai
A16: Emp-15 | B16: Sr. Analyst | C16: Accounting | D16: Speciality Products | E16: Male | F16: 31 | G16: 25-35 | H16: 43043 | I16: 97078 | J16: 0 | K16: 0 | L16: United States | M16: Austin | N16: 43899
A17: Emp-16 | B17: Vice President | C17: Marketing | D17: Research & Development | E17: Female | F17: 41 | G17: 35-45 | H17: 41346 | I17: 249270 | J17: 0.3 | K17: 74781 | L17: United States | M17: Seattle
A18: Emp-17 | B18: Director | C18: Finance | D18: Research & Development | E18: Female | F18: 65 | G18: 65-75 | H18: 37319 | I18: 175837 | J18: 0.2 | K18: 35167.4 | L18: United States | M18: Phoenix
A19: Emp-18 | B19: Sr. Manger | C19: Marketing | D19: Speciality Products | E19: Female | F19: 64 | G19: 55-65 | H19: 37956 | I19: 154828 | J19: 0.13 | K19: 20127.64 | L19: United States | M19: Seattle
A20: Emp-19 | B20: Director | C20: IT | D20: Corporate | E20: Male | F20: 64 | G20: 55-65 | H20: 41581 | I20: 186503 | J20: 0.24 | K20: 44760.72 | L20: United States | M20: Columbus
A21: Emp-20 | B21: Director | C21: Sales | D21: Research & Development | E21: Male | F21: 45 | G21: 45-55 | H21: 37446 | I21: 166331 | J21: 0.18 | K21: 29939.58 | L21: China | M21: Chongqing
A22: Emp-21 | B22: Sr. Manger | C22: IT | D22: Manufacturing | E22: Male | F22: 56 | G22: 55-65 | H22: 40917 | I22: 146140 | J22: 0.1 | K22: 14614 | L22: Brazil | M22: Manaus
A23: Emp-22 | B23: Director | C23: Sales | D23: Manufacturing | E23: Female | F23: 36 | G23: 35-45 | H23: 44288 | I23: 151703 | J23: 0.21 | K23: 31857.63 | L23: United States | M23: Miami
A24: Emp-23 | B24: Director | C24: IT | D24: Research & Development | E24: Male | F24: 59 | G24: 55-65 | H24: 37400 | I24: 172787 | J24: 0.28 | K24: 48380.36 | L24: Brazil | M24: Rio de Janerio
A25: Emp-24 | B25: Analyst | C25: Sales | D25: Speciality Products | E25: Male | F25: 37 | G25: 35-45 | H25: 43713 | I25: 49998 | J25: 0 | K25: 0 | L25: United States | M25: Seattle
A26: Emp-25 | B26: Vice President | C26: Sales | D26: Speciality Products | E26: Male | F26: 44 | G26: 35-45 | H26: 41700 | I26: 207172 | J26: 0.31 | K26: 64223.32 | L26: China | M26: Chongqing
A27: Emp-26 | B27: Director | C27: Human Resources | D27: Speciality Products | E27: Male | F27: 41 | G27: 35-45 | H27: 42111 | I27: 152239 | J27: 0.23 | K27: 35014.97 | L27: United States | M27: Columbus
A28: Emp-27 | B28: Quality Engineer | C28: Engineering | D28: Corporate | E28: Female | F28: 56 | G28: 55-65 | H28: 38388 | I28: 98581 | J28: 0 | K28: 0 | L28: Brazil | M28: Rio de Janerio
... A41: Emp-40 | B41: Enterprise Architect | C41: IT | D41: Corporate | E41: Female | F41: 57 | G41: 55-65 | H41: 34337 | I41: 82872 | J41: 0 | K41: 0 | L41: Brazil | M41: Manaus
A42: Emp-41 | B42: Sr. Business Partner | C42: Human Resources | D42: Speciality Products | E42: Male | F42: 30 | G42: 25-35 | H42: 42884 | I42: 86317 | J42: 0 | K42: 0 | L42: China | M42: Chengdu | N42: 42932
A43: Emp-42 | B43: Manager | C43: Marketing | D43: Speciality Products | E43: Female | F43: 53 | G43: 45-55 | H43: 41601 | I43: 113135 | J43: 0.05 | K43: 5656.75 | L43: United States | M43: Austin
A44: Emp-43 | B44: Vice President | C44: IT | D44: Speciality Products | E44: Male | F44: 52 | G44: 45-55 | H44: 38664 | I44: 199808 | J44: 0.32 | K44: 63938.56 | L44: United States | M44: Seattle
A45: Emp-44 | B45: Account Representative | C45: Sales | D45: Speciality Products | E45: Male | F45: 37 | G45: 35-45 | H45: 41592 | I45: 56037 | J45: 0 | K45: 0 | L45: China | M45: Shanghai
A46: Emp-45 | B46: Sr. Manger | C46: Marketing | D46: Research & Development | E46: Female | F46: 29 | G46: 25-35 | H46: 43609 | I46: 122350 | J46: 0.12 | K46: 14682 | L46: United States | M46: Phoenix
A47: Emp-46 | B47: Enterprise Architect | C47: IT | D47: Research & Development | E47: Male | F47: 40 | G47: 35-45 | H47: 40486 | I47: 92952 | J47: 0 | K47: 0 | L47: United States | M47: Seattle
A48: Emp-47 | B48: Computer Systems Manager | C48: IT | D48: Corporate | E48: Male | F48: 32 | G48: 25-35 | H48: 41353 | I48: 79921 | J48: 0.05 | K48: 3996.05 | L48: United States | M48: Austin
A49: Emp-48 | B49: Director | C49: IT | D49: Research & Development | E49: Female | F49: 37 | G49: 35-45 | H49: 40076 | I49: 167199 | J49: 0.2 | K49: 33439.8 | L49: United States | M49: Seattle
A50: Emp-49 | B50: Quality Engineer | C50: Engineering | D50: Research & Development | E50: Male | F50: 52 | G50: 45-55 | H50: 41199 | I50: 71476 | J50: 0 | K50: 0 | L50: United States | M50: Phoenix
A51: Emp-50 | B51: Director | C51: Engineering | D51: Manufacturing | E51: Female | F51: 45 | G51: 45-55 | H51: 41941 | I51: 189420 | J51: 0.2 | K51: 37884 | L51: United States | M51: Seattle
A52: Emp-51 | B52: HRIS Analyst | C52: Human Resources | D52: Research & Development | E52: Female | F52: 64 | G52: 55-65 | H52: 37184 | I52: 64057 | J52: 0 | K52: 0 | L52: United States | M52: Phoenix
...

Sheet KPI PIVOTABLE EMP1
A1: Count of EMP ID.1 | C1: Row Labels | E1: deparmet
A2: 1000 | C2: Accounting | E2: =COUNTA(C2:C14)-1 -> 7 | H2: Row Labels | I2: country | N2: Row Labels | O2: Count of EMP ID.1
C3: Engineering | H3: Brazil | I3: =COUNTA(H3:H8)-1 -> 3 | N3: 25-35 | O3: 245
C4: Finance | F4: salary | H4: China | N4: 35-45 | O4: 227
C5: Human Resources | E5: Row Labels | F5: =AVERAGE(E6:E1000)-1 -> 113264.97 | H5: United States | N5: 45-55 | O5: 296
C6: IT | E6: 40316 | H6: Grand Total | N6: 55-65 | O6: 217
C7: Marketing | E7: 40752 | K7: dep emp id | N7: 65-75 | O7: 15
C8: Sales | E8: 40897 | K8: Row Labels | L8: Count of EMP ID.1 | N8: Grand Total | O8: 1000
C9: Grand Total | E9: 41336 | H9: salary by dep | K9: Accounting | L9: 96
E10: 41429 | H10: Row Labels | I10: Sum of Annual Salary | K10: Engineering | L10: 158
E11: 41545 | H11: Accounting | I11: 11822107 | K11: Finance | L11: 120
E12: 41561 | H12: Engineering | I12: 17227563 | K12: Human Resources | L12: 125
E13: 41673 | H13: Finance | I13: 14736347 | K13: IT | L13: 241 | N13: country emp
E14: 41728 | H14: Human Resources | I14: 14757305 | K14: Marketing | L14: 120 | N14: Row Labels | O14: Count of EMP ID.1
E15: 41844 | H15: IT | I15: 23567499 | K15: Sales | L15: 140 | N15: Brazil | O15: 139
E16: 41859 | H16: Marketing | I16: 15559564 | K16: Grand Total | L16: 1000 | N16: China | O16: 218
E17: 43001 | H17: Sales | I17: 15546980 | N17: United States | O17: 643
E18: 43080 | H18: Grand Total | I18: 113217365 | K18: age wise emp id | N18: Grand Total | O18: 1000
E19: 43336 | K19: Row Labels | L19: Count of EMP ID.1
E20: 43363 | K20: Female | L20: 518
E21: 43391 | K21: Male | L21: 482
E22: 44614 | K22: Grand Total | L22: 1000
E23: 44732
E24: 44735
E25: 45049
E26: 45061
E27: 45206
E28: 45286 | O28: Row Labels | P28: Count of EMP ID.1
E29: 45295 | O29: Account Representative | P29: 21
E30: 45369 | O30: Analyst | P30: 51
E31: 45819 | O31: Analyst II | P31: 53
E32: 46081 | O32: Automation Engineer | P32: 7
E33: 46727 | O33: Business Partner | P33: 19
E34: 46833 | O34: Cloud Infrastructure Architect | P34: 15
E35: 46845 | O35: Computer Systems Manager | P35: 21
E36: 46878 | O36: Controls Engineer | P36: 15
E37: 47032 | O37: Development Engineer | P37: 19
E38: 47071 | O38: Director | P38: 121
E39: 47387 | O39: Engineering Manager | P39: 20
E40: 47913 | O40: Enterprise Architect | P40: 18
...

Sheet Dashboard EPM
A1: TOTAL EMP | E1: TOTAL DEPARTMENT | H1: EMP DATA REPORT | O1: TOTAL COUNTRY | S1: AVG SALAY
A2: ='KPI PIVOTABLE EMP1'!$A$2 -> 1000 | E2: ='KPI PIVOTABLE EMP1'!$E$2 -> 7 | O2: ='KPI PIVOTABLE EMP1'!$I$3 -> 3 | S2: ='KPI PIVOTABLE EMP1'!$F$5 -> 113264.97
